Workbook

Sheet Cover & Assumptions
B2: TYRE SPOT LIMITED — LBO MODEL
B3: Illustrative founder-succession buyout · Anchored on Companies House FY25 audited accounts (CRN 02854187)
B4: Prepared by A. Kumbhar · For discussion only · NOT a deal indication
B6: ASSUMPTIONS & KEY CAVEATS
B7: • Screening model. Entry anchors sourced from Companies House Tyre Spot Limited FY March 2025 audited accounts.
B8: • Every input is colour-coded and tagged.
B9: • VERIFIED (green) = traced to Companies House Tyre Spot Limited FY March 2025 filing (CRN 02854187).
B10: • CALCULABLE (blue) = derived by formula from verified inputs.
B11: • ASSUMPTION (amber) = modelling choice; returns rest on these.
B12: • FLAGGED (purple) = not yet fully sourced; confirm before relying on it.
B13: • Biggest swing factor: admin discipline execution. £5.5m → £8.3m admin growth FY22-FY25 is the load-bearing assumption to reverse.
B15: SOURCING LEGEND
B16: VERIFIED | C16: Companies House Tyre Spot Limited FY March 2025, CRN 02854187
B17: CALCULABLE | C17: Arithmetic from verified inputs
B18: ASSUMPTION | C18: Modelling choice — illustrative, not a fact or deal indication
B19: FLAGGED | C19: Not yet fully sourced — confirm before relying on it
B20: Colour: blue = input you can change · black = formula · green = link from this workbook · grey = source note
B22: TYRE SPOT 10-YR MARGIN HISTORY + PEER BENCHMARKS — Bloomberg
B23: £m / % | C23: FY17 | D23: FY18 | E23: FY19 | F23: FY20 | G23: FY21 | H23: FY22 | I23: FY23 | J23: FY24 | K23: FY25
B24: Revenue (£m) | C24: 15.42 | D24: 16.47 | E24: 18.21 | F24: 17.33 | G24: 19.86 | H24: 26.1 | I24: 27.93 | J24: 31.49 | K24: 35.23
B25: EBITDA (£m) | C25: 0.15 | D25: 0.39 | E25: 0.75 | F25: 0.68 | G25: 1.33 | H25: 1.21 | I25: 0.86 | J25: 1.17 | K25: 1.13
B26: EBITDA margin | C26: 0.0095 | D26: 0.0234 | E26: 0.0412 | F26: 0.0395 | G26: 0.0669 | H26: 0.0463 | I26: 0.0309 | J26: 0.0371 | K26: 0.0322
B27: Source: Bloomberg 9136763Z LN Equity, FY17-FY25. 10-yr avg margin ~3.4%; 5-yr avg (FY21-25) 4.27%; FY21 peak 6.69%.
B32: ENTRY ANCHORS — Companies House FY March 2025 (£m unless stated)
B33: FY25 Revenue (£m) | C33: 35.017 | E33: VERIFIED | F33: CH Tyre Spot Ltd FY25 p.12 — Statement of Income & Retained Earnings
B34: FY25 Cost of sales (£m) | C34: -26.009 | E34: VERIFIED | F34: CH FY25 p.12
B35: FY25 Gross profit (£m) | C35: =C33+C34 -> 9.008 | E35: CALCULABLE | F35: Revenue − COGS
B36: FY25 Operating profit (£m) | C36: 0.753 | E36: VERIFIED | F36: CH FY25 p.12
B37: FY25 Depreciation (£m) | C37: 0.368 | E37: VERIFIED | F37: CH FY25 Note 4 (p.20)
B38: FY25 Amortisation (£m) | C38: 0.005 | E38: VERIFIED | F38: CH FY25 Note 4 (p.20)
B39: FY25 EBITDA (£m) | C39: =C36+C37+C38 -> 1.126 | E39: CALCULABLE | F39: Op profit + D&A — reconciles to £1.13m
B40: FY25 EBITDA margin | C40: =C39/C33 -> 0.03215581 | E40: CALCULABLE | F40: Derived ≈3.2%
B42: Bank loans (£m) | C42: 0.415 | E42: VERIFIED | F42: CH FY25 Note 19 (p.25)
B43: Bank overdrafts (£m) | C43: 0.807 | E43: VERIFIED | F43: CH FY25 Note 19 (p.25)
B44: Cash (£m) | C44: 0.03 | E44: VERIFIED | F44: CH FY25 Balance Sheet (p.13)
B45: Net debt at entry (£m) | C45: =C42+C43-C44 -> 1.192 | E45: CALCULABLE | F45: Bank loans + overdraft − cash = £1.19m
B46: Tangible fixed assets (£m) | C46: 4.516 | E46: VERIFIED | F46: CH FY25 BS — of which £2.79m freehold pledged as security (Note 12, p.23)
B47: Stocks (£m) | C47: 4.909 | E47: VERIFIED | F47: CH FY25 BS — funds wholesale book; 69 days COGS
B48: Trade debtors (£m) | C48: 3.614 | E48: VERIFIED | F48: CH FY25 Note 16
B49: Retained earnings c/f (£m) | C49: 6.621 | E49: VERIFIED | F49: CH FY25 BS
...

Sheet Model
B1: TYRE SPOT — LBO MODEL
B3: INPUTS — key drivers (links to Cover & Assumptions sheet)
B5: Purchase Assumptions | F5: Financing Assumptions
B6: Purchase EBITDA (£m) | C6: ='Cover & Assumptions'!C39 -> 1.126 | F6: % LTC (senior debt / EV) | G6: ='Cover & Assumptions'!C54/'Cover & Assumptions'!C53 -> 0.54058228 | H6: Interest Rate | I6: ='Cover & Assumptions'!C68 -> 0.085
B7: Purchase Multiple (x) | C7: ='Cover & Assumptions'!C52 -> 5.75 | F7: Aggregate Financing (£m) | G7: ='Cover & Assumptions'!C54 -> 3.5
B8: Purchase EV (£m) | C8: =C6*C7 -> 6.4745
B9: Plus: Cash (£m) | C9: ='Cover & Assumptions'!C44 -> 0.03
B10: Less: Existing Debt (£m) | C10: =-('Cover & Assumptions'!C42+'Cover & Assumptions'!C43+'Cover & Assumptions'!C79) -> -1.249
B11: Purchase Equity Value (£m) | C11: =C8+C9+C10 -> 5.2555
B13: P&L Assumptions | F13: Exit Assumptions
B14: Revenue Growth (4-yr avg) | C14: =AVERAGE('Cover & Assumptions'!C62:F62) -> 0.0525 | F14: Exit Multiple (x LTM EBITDA) | G14: ='Cover & Assumptions'!C74 -> 6
B15: Y4 EBITDA Margin Target | C15: ='Cover & Assumptions'!F63 -> 0.046 | F15: Hold Period (years) | G15: ='Cover & Assumptions'!C73 -> 4
B16: Tax Rate | C16: ='Cover & Assumptions'!C67 -> 0.25
B18: Uses of Capital (£m) | F18: Sources of Capital (£m)
B19: Purchase Company's Equity | C19: =C11 -> 5.2555 | F19: % LTC | G19: £m
B20: Retire Existing Debt | C20: =-C10 -> 1.249 | F20: Aggregate Financing | G20: =G6 -> 0.54058228 | H20: =G7 -> 3.5
B21: Working Capital Injection | C21: ='Cover & Assumptions'!C58 -> 0.4 | F21: Management Rollover | G21: =H21/C24 -> 0.027799013 | H21: ='Cover & Assumptions'!C56 -> 0.2
B22: Transaction Expenses | C22: ='Cover & Assumptions'!C57 -> 0.29 | F22: Sponsor Equity (plug) | G22: =1-G20-G21 -> 0.4316187 | H22: =C24-H20-H21 -> 3.4945
B23: Total Uses | C23: =SUM(C19:C22) -> 7.1945 | F23: Total Sources | G23: =SUM(G20:G22) -> 1 | H23: =SUM(H20:H22) -> 7.1945
B24: Sources = Uses? | C24: =C23 -> 7.1945 | F24: Ties? | G24: =IF(ROUND(H23-C23,2)=0,"OK","ERROR") -> OK
B26: Detailed Operating Model + Debt Schedule + Returns + Sensitivity below
B30: Revenue | C30: ='Cover & Assumptions'!$C$33 -> 35.017 | D30: =C30*(1+'Cover & Assumptions'!C62) -> 37.81836 | E30: =D30*(1+'Cover & Assumptions'!D62) -> 40.087462 | F30: =E30*(1+'Cover & Assumptions'!E62) -> 41.69096 | G30: =F30*(1+'Cover & Assumptions'!F62) -> 42.941689
B31: EBITDA margin | C31: ='Cover & Assumptions'!$C$40 -> 0.03215581 | D31: ='Cover & Assumptions'!C63 -> 0.04 | E31: ='Cover & Assumptions'!D63 -> 0.042 | F31: ='Cover & Assumptions'!E63 -> 0.044 | G31: ='Cover & Assumptions'!F63 -> 0.046
B32: EBITDA | C32: =C30*C31 -> 1.126 | D32: =D30*D31 -> 1.5127344 | E32: =E30*E31 -> 1.6836734 | F32: =F30*F31 -> 1.8344022 | G32: =G30*G31 -> 1.9753177
B33: Depreciation & amortisation | C33: =-C30*'Cover & Assumptions'!$C$64 -> -0.373 | D33: =-D30*'Cover & Assumptions'!$C$64 -> -0.40284 | E33: =-E30*'Cover & Assumptions'!$C$64 -> -0.4270104 | F33: =-F30*'Cover & Assumptions'!$C$64 -> -0.44409082 | G33: =-G30*'Cover & Assumptions'!$C$64 -> -0.45741354
B34: EBIT | C34: =C32+C33 -> 0.753 | D34: =D32+D33 -> 1.1098944 | E34: =E32+E33 -> 1.256663 | F34: =F32+F33 -> 1.3903114 | G34: =G32+G33 -> 1.5179041
B35: Cash interest (senior) | C35: 0 | D35: =-D54 -> -0.2975 | E35: =-E54 -> -0.26775 | F35: =-F54 -> -0.238 | G35: =-G54 -> -0.20825
B36: Profit before tax | C36: =C34+C35 -> 0.753 | D36: =D34+D35 -> 0.8123944 | E36: =E34+E35 -> 0.98891299 | F36: =F34+F35 -> 1.1523114 | G36: =G34+G35 -> 1.3096541
B37: Cash tax | C37: =-MAX(0,C36)*'Cover & Assumptions'!$C$67 -> -0.18825 | D37: =-MAX(0,D36)*'Cover & Assumptions'!$C$67 -> -0.2030986 | E37: =-MAX(0,E36)*'Cover & Assumptions'!$C$67 -> -0.24722825 | F37: =-MAX(0,F36)*'Cover & Assumptions'!$C$67 -> -0.28807786 | G37: =-MAX(0,G36)*'Cover & Assumptions'!$C$67 -> -0.32741354
B38: Net profit | C38: =C36+C37 -> 0.56475 | D38: =D36+D37 -> 0.6092958 | E38: =E36+E37 -> 0.74168474 | F38: =F36+F37 -> 0.86423357 | G38: =G36+G37 -> 0.98224061
B40: FREE CASH FLOW BUILD
B41: EBITDA | C41: =C32 -> 1.126 | D41: =D32 -> 1.5127344 | E41: =E32 -> 1.6836734 | F41: =F32 -> 1.8344022 | G41: =G32 -> 1.9753177
B42: Less: capex | C42: =-C30*'Cover & Assumptions'!$C$65 -> -0.70034 | D42: =-D30*'Cover & Assumptions'!$C$65 -> -0.7563672 | E42: =-E30*'Cover & Assumptions'!$C$65 -> -0.80174923 | F42: =-F30*'Cover & Assumptions'!$C$65 -> -0.8338192 | G42: =-G30*'Cover & Assumptions'!$C$65 -> -0.85883378
B43: Less: change in working capital | C43: 0 | D43: =-(D30-C30)*'Cover & Assumptions'!$C$66 -> -0.61349784 | E43: =-(E30-D30)*'Cover & Assumptions'!$C$66 -> -0.49693325 | F43: =-(F30-E30)*'Cover & Assumptions'!$C$66 -> -0.35116616 | G43: =-(G30-F30)*'Cover & Assumptions'!$C$66 -> -0.27390961
B44: Less: cash interest | C44: =C35 -> 0 | D44: =D35 -> -0.2975 | E44: =E35 -> -0.26775 | F44: =F35 -> -0.238 | G44: =G35 -> -0.20825
B45: Less: cash tax | C45: =C37 -> -0.18825 | D45: =D37 -> -0.2030986 | E45: =E37 -> -0.24722825 | F45: =F37 -> -0.28807786 | G45: =G37 -> -0.32741354
B46: Free cash flow (pre-debt repayment) | C46: =SUM(C41:C45) -> 0.23741 | D46: =SUM(D41:D45) -> -0.35772924 | E46: =SUM(E41:E45) -> -0.12998734 | F46: =SUM(F41:F45) -> 0.12333902 | G46: =SUM(G41:G45) -> 0.30691077
B48: ACQUISITION DEBT SCHEDULE & CASH SWEEP
B49: £m | C49: FY25A (Entry) | D49: Year 1 | E49: Year 2 | F49: Year 3 | G49: Year 4
B50: Opening Acquisition debt | C50: ='Cover & Assumptions'!$C$54 -> 3.5 | D50: =C50 -> 3.5 | E50: =D55 -> 3.15 | F50: =E55 -> 2.8 | G50: =F55 -> 2.45
...
