Workbook

Sheet Cover & Assumptions
B2: SIGMA COMPONENTS HOLDINGS -LBO MODEL
B3: Illustrative secondary buyout · Anchored on FactSet Private Company + Companies House (CRN 10010945)
B4: Prepared by A. Kumbhar · For discussion only · NOT a deal indication
B6: ASSUMPTIONS & KEY CAVEATS
B7: • Screening model. Entry anchors now sourced from FactSet Private Company + Companies House.
B8: • Every input is colour-coded and tagged.
B9: • VERIFIED (green) = traced to FactSet Private Company or Companies House FY May 2025.
B10: • CALCULABLE (blue) = derived by formula from verified inputs.
B11: • ASSUMPTION (amber) = modelling choice, returns rests on these
B12: • FLAGGED (purple) = not yet fully sourced -confirm before relying on it.
B13: • Biggest swing factor remains the preference settlement haircut -a pure assumption.
B15: SOURCING LEGEND
B16: VERIFIED | C16: FactSet Private Company / Companies House FY May 2025, CRN 10010945
B17: CALCULABLE | C17: Arithmetic from verified inputs
B18: ASSUMPTION | C18: Modelling choice -illustrative, not a fact or deal indication
B19: FLAGGED | C19: Not yet fully sourced -confirm before relying on it
B20: Colour: blue = input you can change · black = formula · green = link from this workbook
B22: EBITDA MARGIN HISTORY -supports the margin-recovery thesis
B23: £m / % | C23: FY19 | D23: FY20 | E23: FY21 | F23: FY22 | G23: FY23 | H23: FY24 | I23: FY25
B24: EBITDA (£m) | C24: 9.44 | D24: -5.758 | E24: -3.012 | F24: 2.203 | G24: 4.121 | H24: 5.963 | I24: 6.487
B25: EBITDA margin | C25: 0.1849 | D25: -0.1354 | E25: -0.1353 | F25: 0.083 | G25: 0.1158 | H25: 0.1423 | I25: 0.1439
B26: Source: FactSet Private Company, Sigma Components Holdings (CONSOL). Ran at 18.5% pre-COVID (FY19); current 14.4% is recovery, not a heroic projection. Underpins the value-creation margin lever.
B28: ASSUMPTIONS -every driver in one place
B30: ENTRY ANCHORS -FactSet Private Company + Companies House FY May 2025
B31: FY25 Revenue (£m) | C31: 45.083 | E31: VERIFIED | F31: FactSet Private Co (CONSOL); CH P&L page 14
B32: FY25 Gross profit (£m) | C32: 12.2 | E32: VERIFIED | F32: Companies House consolidated P&L, page 14
B33: FY25 Operating profit / EBIT (£m) | C33: 4.359 | E33: VERIFIED | F33: FactSet Private Co (CONSOL) FY May 2025
B34: FY25 D&A (£m) | C34: 2.128 | E34: VERIFIED | F34: FactSet Private Co (CONSOL) FY May 2025
B35: FY25 EBITDA (£m) | C35: =C33+C34 -> 6.487 | E35: CALCULABLE | F35: EBIT + D&A (both sourced) -reconciles to FactSet EBITDA £6.487m
B36: FY25 EBITDA margin | C36: =C35/C31 -> 0.14389016 | E36: CALCULABLE | F36: Derived (≈14.4%, matches FactSet)
B37: Senior bank debt (£m) | C37: 15.9 | E37: VERIFIED | F37: CH Note 20 + charge filing 5-Jun-25 (FactSet borrowings £15.8m)
B38: Finance leases (£m) | C38: 0.6 | E38: VERIFIED | F38: Companies House Note 20
B39: Cash (£m) | C39: 4.838 | E39: VERIFIED | F39: FactSet Private Co (CONSOL) FY May 2025
B40: Net senior debt (£m) | C40: =C37+C38-C39 -> 11.662 | E40: CALCULABLE | F40: Senior + leases - cash
B41: Preference principal (£m) | C41: 33.2 | E41: VERIFIED | F41: Companies House Note 22 -12pct coupon, repayable 31 Dec 2026
B42: Accrued PIK interest (£m) | C42: 49 | E42: VERIFIED | F42: Companies House Note 19 -accrued pref interest £48.954m
B43: Total preference stack (£m) | C43: =C41+C42 -> 82.2 | E43: VERIFIED | F43: Principal + accrued PIK
B45: TRANSACTION ASSUMPTIONS -ALL ILLUSTRATIVE, NOT DEAL INDICATIONS
B46: Entry EV / EBITDA multiple (x) | C46: 7 | E46: CALCULABLE | F46: Comp-supported: ~10x listed through-cycle median less
B47: Implied Entry Enterprise Value (£m) | C47: =C35*C46 -> 45.409 | E47: CALCULABLE | F47: EBITDA × entry multiple (informational)
...

Sheet Model
B1: SIGMA COMPONENTS -LBO MODEL
B3: SOURCES & USES -illustrative entry structure
B4: USES OF FUNDS (£m) | F4: SOURCES OF FUNDS (£m)
B5: Take out existing senior debt | C5: ='Cover & Assumptions'!$C$37 -> 15.9 | F5: Acquisition debt | G5: ='Cover & Assumptions'!$C$51 -> 26
B6: Settle preference stack (after haircut) | C6: ='Cover & Assumptions'!$C$49 -> 40.278 | F6: Mngmnt rollover | G6: ='Cover & Assumptions'!$C$52 -> 2
B7: Transaction fees | C7: ='Cover & Assumptions'!$C$50 -> 2.1 | F7: Rubicon equity | G7: =C8-G5-G6 -> 30.278
B8: TOTAL USES | C8: =SUM(C5:C7) -> 58.278 | F8: TOTAL SOURCES | G8: =SUM(G5:G7) -> 58.278
F9: Rubicon Equity | G9: =G7 -> 30.278
E10: Check: Sources = Uses | G10: =IF(ROUND(G8-C8,2)=0,"OK","ERROR") -> OK
B11: Sponsor equity is the plug. Pref settlement (haircut on Cover & Assumptions) is the largest single use.
B13: OPERATING MODEL -5-year projection
B14: £m | C14: FY25A (Entry) | D14: Year 1 | E14: Year 2 | F14: Year 3 | G14: Year 4 | H14: Year 5
B15: Revenue | C15: ='Cover & Assumptions'!$C$31 -> 45.083 | D15: =C15*(1+'Cover & Assumptions'!$C$56) -> 47.33715 | E15: =D15*(1+'Cover & Assumptions'!$C$56) -> 49.704008 | F15: =E15*(1+'Cover & Assumptions'!$C$56) -> 52.189208 | G15: =F15*(1+'Cover & Assumptions'!$C$56) -> 54.798668 | H15: =G15*(1+'Cover & Assumptions'!$C$56) -> 57.538602
B16: EBITDA margin | C16: ='Cover & Assumptions'!$C$36 -> 0.14389016 | D16: ='Cover & Assumptions'!$C$36+('Cover & Assumptions'!$C$57-'Cover & Assumptions'!$C$36)*1/'Cover & Assumptions'!$C$67 -> 0.14911213 | E16: ='Cover & Assumptions'!$C$36+('Cover & Assumptions'!$C$57-'Cover & Assumptions'!$C$36)*2/'Cover & Assumptions'!$C$67 -> 0.15433409 | F16: ='Cover & Assumptions'!$C$36+('Cover & Assumptions'!$C$57-'Cover & Assumptions'!$C$36)*3/'Cover & Assumptions'!$C$67 -> 0.15955606 | G16: ='Cover & Assumptions'!$C$36+('Cover & Assumptions'!$C$57-'Cover & Assumptions'!$C$36)*4/'Cover & Assumptions'!$C$67 -> 0.16477803 | H16: ='Cover & Assumptions'!$C$36+('Cover & Assumptions'!$C$57-'Cover & Assumptions'!$C$36)*5/'Cover & Assumptions'!$C$67 -> 0.17
B17: EBITDA | C17: =C15*C16 -> 6.487 | D17: =D15*D16 -> 7.0585431 | E17: =E15*E16 -> 7.671023 | F17: =F15*F16 -> 8.3271046 | G17: =G15*G16 -> 9.0296167 | H17: =H15*H16 -> 9.7815623
B18: Depreciation & amortisation | C18: =-C15*'Cover & Assumptions'!$C$58 -> -2.128 | D18: =-D15*'Cover & Assumptions'!$C$58 -> -2.2344 | E18: =-E15*'Cover & Assumptions'!$C$58 -> -2.34612 | F18: =-F15*'Cover & Assumptions'!$C$58 -> -2.463426 | G18: =-G15*'Cover & Assumptions'!$C$58 -> -2.5865973 | H18: =-H15*'Cover & Assumptions'!$C$58 -> -2.7159272
B19: EBIT | C19: =C17+C18 -> 4.359 | D19: =D17+D18 -> 4.8241431 | E19: =E17+E18 -> 5.324903 | F19: =F17+F18 -> 5.8636786 | G19: =G17+G18 -> 6.4430194 | H19: =H17+H18 -> 7.0656351
B20: Cash interest (senior) | C20: 0 | D20: =-D37 -> -2.21 | E20: =-E37 -> -2.0180878 | F20: =-F37 -> -1.7807547 | G20: =-G37 -> -1.4926185 | H20: =-H37 -> -1.1477881
B21: Profit before tax | C21: =C19+C20 -> 4.359 | D21: =D19+D20 -> 2.6141431 | E21: =E19+E20 -> 3.3068152 | F21: =F19+F20 -> 4.0829239 | G21: =G19+G20 -> 4.9504009 | H21: =H19+H20 -> 5.917847
B22: Cash tax | C22: =-MAX(0,C21)*'Cover & Assumptions'!$C$61 -> -1.08975 | D22: =-MAX(0,D21)*'Cover & Assumptions'!$C$61 -> -0.65353578 | E22: =-MAX(0,E21)*'Cover & Assumptions'!$C$61 -> -0.82670381 | F22: =-MAX(0,F21)*'Cover & Assumptions'!$C$61 -> -1.020731 | G22: =-MAX(0,G21)*'Cover & Assumptions'!$C$61 -> -1.2376002 | H22: =-MAX(0,H21)*'Cover & Assumptions'!$C$61 -> -1.4794617
B23: Net profit | C23: =C21+C22 -> 3.26925 | D23: =D21+D22 -> 1.9606073 | E23: =E21+E22 -> 2.4801114 | F23: =F21+F22 -> 3.0621929 | G23: =G21+G22 -> 3.7128007 | H23: =H21+H22 -> 4.4383852
B25: FREE CASH FLOW BUILD
B26: EBITDA | C26: =C17 -> 6.487 | D26: =D17 -> 7.0585431 | E26: =E17 -> 7.671023 | F26: =F17 -> 8.3271046 | G26: =G17 -> 9.0296167 | H26: =H17 -> 9.7815623
B27: Less: capex | C27: =-C15*'Cover & Assumptions'!$C$59 -> -0.9647762 | D27: =-D15*'Cover & Assumptions'!$C$59 -> -1.013015 | E27: =-E15*'Cover & Assumptions'!$C$59 -> -1.0636658 | F27: =-F15*'Cover & Assumptions'!$C$59 -> -1.116849 | G27: =-G15*'Cover & Assumptions'!$C$59 -> -1.1726915 | H27: =-H15*'Cover & Assumptions'!$C$59 -> -1.2313261
B28: Less: change in working capital | C28: 0 | D28: =-(D15-C15)*'Cover & Assumptions'!$C$60 -> -0.9242015 | E28: =-(E15-D15)*'Cover & Assumptions'!$C$60 -> -0.97041158 | F28: =-(F15-E15)*'Cover & Assumptions'!$C$60 -> -1.0189322 | G28: =-(G15-F15)*'Cover & Assumptions'!$C$60 -> -1.0698788 | H28: =-(H15-G15)*'Cover & Assumptions'!$C$60 -> -1.1233727
B29: Less: cash interest | C29: =C20 -> 0 | D29: =D20 -> -2.21 | E29: =E20 -> -2.0180878 | F29: =F20 -> -1.7807547 | G29: =G20 -> -1.4926185 | H29: =H20 -> -1.1477881
B30: Less: cash tax | C30: =C22 -> -1.08975 | D30: =D22 -> -0.65353578 | E30: =E22 -> -0.82670381 | F30: =F22 -> -1.020731 | G30: =G22 -> -1.2376002 | H30: =H22 -> -1.4794617
B31: Free cash flow (pre-debt repayment) | C31: =C26+C27+C28+C29+C30 -> 4.4324738 | D31: =D26+D27+D28+D29+D30 -> 2.2577908 | E31: =E26+E27+E28+E29+E30 -> 2.7921541 | F31: =F26+F27+F28+F29+F30 -> 3.3898377 | G31: =G26+G27+G28+G29+G30 -> 4.0568277 | H31: =H26+H27+H28+H29+H30 -> 4.7996136
B33: ACQUISITION DEBT SCHEDULE & CASH SWEEP
B34: £m | C34: FY25A (Entry) | D34: Year 1 | E34: Year 2 | F34: Year 3 | G34: Year 4 | H34: Year 5
B35: Opening Acquisition debt | C35: ='Cover & Assumptions'!$C$51 -> 26 | D35: =C35 -> 26 | E35: =D38 -> 23.742209 | F35: =E38 -> 20.950055 | G35: =F38 -> 17.560217 | H35: =G38 -> 13.50339
B36: Interest rate | C36: ='Cover & Assumptions'!$C$62 -> 0.085 | D36: ='Cover & Assumptions'!$C$62 -> 0.085 | E36: ='Cover & Assumptions'!$C$62 -> 0.085 | F36: ='Cover & Assumptions'!$C$62 -> 0.085 | G36: ='Cover & Assumptions'!$C$62 -> 0.085 | H36: ='Cover & Assumptions'!$C$62 -> 0.085
B37: Cash interest | C37: 0 | D37: =D35*D36 -> 2.21 | E37: =E35*E36 -> 2.0180878 | F37: =F35*F36 -> 1.7807547 | G37: =G35*G36 -> 1.4926185 | H37: =H35*H36 -> 1.1477881
B38: Closing senior debt | C38: =C35 -> 26 | D38: =MAX(0,D35-D39) -> 23.742209 | E38: =MAX(0,E35-E39) -> 20.950055 | F38: =MAX(0,F35-F39) -> 17.560217 | G38: =MAX(0,G35-G39) -> 13.50339 | H38: =MAX(0,H35-H39) -> 8.703776
B39: Cash sweep (repayment) | C39: 0 | D39: =MIN(D35,MAX(0,D31)*'Cover & Assumptions'!$C$63) -> 2.2577908 | E39: =MIN(E35,MAX(0,E31)*'Cover & Assumptions'!$C$63) -> 2.7921541 | F39: =MIN(F35,MAX(0,F31)*'Cover & Assumptions'!$C$63) -> 3.3898377 | G39: =MIN(G35,MAX(0,G31)*'Cover & Assumptions'!$C$63) -> 4.0568277 | H39: =MIN(H35,MAX(0,H31)*'Cover & Assumptions'!$C$63) -> 4.7996136
B41: Net senior debt at exit (£m) | C41: =H38-'Cover & Assumptions'!$C$64 -> 5.703776 | D41: (closing Y5 senior less minimum cash; pref settled at entry)
B42: Interest charged on opening balance -no circular reference. 100% of FCF sweeps the facility before cash builds.
B44: RETURNS -equity bridge
B45: EXIT (YEAR 5) -ILLUSTRATIVE
B46: Year 5 EBITDA | C46: =H17 -> 9.7815623
...

Sheet Sheet1
B2: SIGMA COMPONENTS HOLDINGS -LBO MODEL | P2: USES | T2: SOURCES
B3: Illustrative secondary buyout · Anchored on FactSet Private Company + Companies House (CRN 10010945) | P3: Take out bank debt | Q3: =15.9 -> 15.9 | T3: Acquisition debt | U3: =26 -> 26
B4: Prepared by A. Kumbhar · For discussion only · NOT a deal indication | P4: Transaction fees | Q4: =2.1 -> 2.1 | T4: Mngmnt roll | U4: =2 -> 2
P5: Pref settlement after haircut | Q5: =40.3 -> 40.3 | T5: Rubicon Equity | U5: =Q6-SUM(U3:U4) -> 30.3
B6: EBITDA MARGIN HISTORY -supports the margin-recovery thesis | P6: Total | Q6: =SUM(Q3:Q5) -> 58.3 | T6: Total | U6: =SUM(U3:U5) -> 58.3
B7: £m / % | C7: FY19 | D7: FY20 | E7: FY21 | F7: FY22 | G7: FY23 | H7: FY24 | I7: FY25
B8: EBITDA (£m) | C8: 9.44 | D8: -5.758 | E8: -3.012 | F8: 2.203 | G8: 4.121 | H8: 5.963 | I8: 6.487 | R8: USES = SOURCES
B9: EBITDA margin | C9: 0.1849 | D9: -0.1354 | E9: -0.1353 | F9: 0.083 | G9: 0.1158 | H9: 0.1423 | I9: 0.1439
B10: Source: FactSet Private Company, Sigma Components Holdings (CONSOL). Ran at 18.5% pre-COVID (FY19); current 14.4% is recovery, not a heroic projection. Underpins the value-creation margin lever.
P11: OPERATING MODEL
B12: ASSUMPTIONS -every driver in one place | Q12: ENTRY | R12: Y1 | S12: Y2 | T12: Y3 | U12: Y4 | V12: Y5
P13: REVENUE | Q13: =C15 -> 45.083 | R13: =Q13*(1+C40) -> 47.33715 | S13: =R13*(1+C40) -> 49.704008 | T13: =S13*(1+C40) -> 52.189208 | U13: =T13*(1+C40) -> 54.798668 | V13: =U13*(1+C40) -> 57.538602
B14: ENTRY ANCHORS -FactSet Private Company + Companies House FY May 2025 | P14: EBITDA MARGIN | Q14: ='Cover & Assumptions'!$C$36 -> 0.14389016 | R14: ='Cover & Assumptions'!$C$36+('Cover & Assumptions'!$C$57-'Cover & Assumptions'!$C$36)*1/'Cover & Assumptions'!$C$67 -> 0.14911213 | S14: ='Cover & Assumptions'!$C$36+('Cover & Assumptions'!$C$57-'Cover & Assumptions'!$C$36)*2/'Cover & Assumptions'!$C$67 -> 0.15433409 | T14: ='Cover & Assumptions'!$C$36+('Cover & Assumptions'!$C$57-'Cover & Assumptions'!$C$36)*3/'Cover & Assumptions'!$C$67 -> 0.15955606 | U14: ='Cover & Assumptions'!$C$36+('Cover & Assumptions'!$C$57-'Cover & Assumptions'!$C$36)*4/'Cover & Assumptions'!$C$67 -> 0.16477803 | V14: ='Cover & Assumptions'!$C$36+('Cover & Assumptions'!$C$57-'Cover & Assumptions'!$C$36)*5/'Cover & Assumptions'!$C$67 -> 0.17
B15: FY25 Revenue (£m) | C15: 45.083 | E15: VERIFIED | F15: FactSet Private Co (CONSOL); CH P&L page 14 | P15: EBITDA | Q15: =Q13*Q14 -> 6.487 | R15: =R13*R14 -> 7.0585431 | S15: =S13*S14 -> 7.671023 | T15: =T13*T14 -> 8.3271046 | U15: =U13*U14 -> 9.0296167 | V15: =V13*V14 -> 9.7815623
B16: FY25 Gross profit (£m) | C16: 12.2 | E16: VERIFIED | F16: Companies House consolidated P&L, page 14 | P16: D&A | Q16: =Q13*4.7% -> 2.118901 | R16: =R13*4.7% -> 2.2248461 | S16: =S13*4.7% -> 2.3360884 | T16: =T13*4.7% -> 2.4528928 | U16: =U13*4.7% -> 2.5755374 | V16: =V13*4.7% -> 2.7043143
B17: FY25 Operating profit / EBIT (£m) | C17: 4.359 | E17: VERIFIED | F17: FactSet Private Co (CONSOL) FY May 2025 | P17: EBIT | Q17: =Q15-Q16 -> 4.368099 | R17: =R15-R16 -> 4.8336971 | S17: =S15-S16 -> 5.3349347 | T17: =T15-T16 -> 5.8742118 | U17: =U15-U16 -> 6.4540793 | V17: =V15-V16 -> 7.077248
B18: FY25 D&A (£m) | C18: 2.128 | E18: VERIFIED | F18: FactSet Private Co (CONSOL) FY May 2025 -was estimate, now sourced
B19: FY25 EBITDA (£m) | C19: =C17+C18 -> 6.487 | E19: CALCULABLE | F19: EBIT + D&A (both sourced) -reconciles to FactSet EBITDA £6.487m | P19: Cash Interest | Q19: =Q36 -> 0 | R19: =R36 -> -2.21 | S19: =S36 -> -2.0166813 | T19: =T36 -> -1.7777818 | U19: =U36 -> -1.4879055 | V19: =V36 -> -1.1411465
B20: FY25 EBITDA margin | C20: =C19/C15 -> 0.14389016 | E20: CALCULABLE | F20: Derived (≈14.4%, matches FactSet) | P20: EBT (profit befor tax) | Q20: =Q17-Q19 -> 4.368099 | R20: =R17+R19 -> 2.6236971 | S20: =S17+S19 -> 3.3182533 | T20: =T17+T19 -> 4.09643 | U20: =U17+U19 -> 4.9661738 | V20: =V17+V19 -> 5.9361015
B21: Senior bank debt (£m) | C21: 15.9 | E21: VERIFIED | F21: CH Note 20 + charge filing 5-Jun-25 (FactSet borrowings £15.8m) | P21: Cash Tax | Q21: =-(MAX(0,Q20)*25%) -> -1.0920247 | R21: =-(MAX(0,R20)*25%) -> -0.65592426 | S21: =-(MAX(0,S20)*25%) -> -0.82956333 | T21: =-(MAX(0,T20)*25%) -> -1.0241075 | U21: =-(MAX(0,U20)*25%) -> -1.2415434 | V21: =-(MAX(0,V20)*25%) -> -1.4840254
B22: Finance leases (£m) | C22: 0.6 | E22: VERIFIED | F22: Companies House Note 20 | P22: Net Profit | Q22: =SUM(Q20:Q21) -> 3.2760742 | R22: =SUM(R20:R21) -> 1.9677728 | S22: =SUM(S20:S21) -> 2.48869 | T22: =SUM(T20:T21) -> 3.0723225 | U22: =SUM(U20:U21) -> 3.7246303 | V22: =SUM(V20:V21) -> 4.4520761
B23: Cash (£m) | C23: 4.838 | E23: VERIFIED | F23: FactSet Private Co (CONSOL) FY May 2025 -was estimate, now sourced
B24: Net senior debt (£m) | C24: =C21+C22-C23 -> 11.662 | E24: CALCULABLE | F24: Senior + leases - cash | P24: Free Cash Flow FCF
B25: Preference principal (£m) | C25: 33.2 | E25: VERIFIED | F25: Companies House Note 22 -12pct coupon, repayable 31 Dec 2026 per Note 20 | P25: EBITDA | Q25: =Q15 -> 6.487 | R25: =R15 -> 7.0585431 | S25: =S15 -> 7.671023 | T25: =T15 -> 8.3271046 | U25: =U15 -> 9.0296167 | V25: =V15 -> 9.7815623
B26: Accrued PIK interest (£m) | C26: 49 | E26: VERIFIED | F26: Companies House Note 19 -accrued pref interest £48.954m | P26: Less Capex | Q26: =-Q13*2.1% -> -0.946743 | R26: =-R13*2.1% -> -0.99408015 | S26: =-S13*2.1% -> -1.0437842 | T26: =-T13*2.1% -> -1.0959734 | U26: =-U13*2.1% -> -1.150772 | V26: =-V13*2.1% -> -1.2083106
B27: Total preference stack (£m) | C27: =C25+C26 -> 82.2 | E27: VERIFIED | F27: Principal + accrued PIK | P27: Less NWC | Q27: =0 -> 0 | R27: =-((R13-Q13)*41%) -> -0.9242015 | S27: =-((S13-R13)*41%) -> -0.97041158 | T27: =-((T13-S13)*41%) -> -1.0189322 | U27: =-((U13-T13)*41%) -> -1.0698788 | V27: =-((V13-U13)*41%) -> -1.1233727
P28: Less Cash Interest | Q28: =Q36 -> 0 | R28: =R36 -> -2.21 | S28: =S36 -> -2.0166813 | T28: =T36 -> -1.7777818 | U28: =U36 -> -1.4879055 | V28: =V36 -> -1.1411465
B29: TRANSACTION ASSUMPTIONS -ALL ILLUSTRATIVE, NOT DEAL INDICATIONS | P29: Less Cash tax | Q29: =Q21 -> -1.0920247 | R29: =R21 -> -0.65592426 | S29: =S21 -> -0.82956333 | T29: =T21 -> -1.0241075 | U29: =U21 -> -1.2415434 | V29: =V21 -> -1.4840254
B30: Entry EV / EBITDA multiple (x) | C30: 7 | E30: CALCULABLE | F30: Comp-supported: ~10x listed through-cycle median less ~30pct size/illiquidity (see Comp Analysis) | P30: FCF (pre debt repayment) | Q30: =SUM(Q25:Q29) -> 4.4482323 | R30: =SUM(R25:R29) -> 2.2743372 | S30: =SUM(S25:S29) -> 2.8105826 | T30: =SUM(T25:T29) -> 3.4103097 | U30: =SUM(U25:U29) -> 4.079517 | V30: =SUM(V25:V29) -> 4.824707
B31: Implied Entry Enterprise Value (£m) | C31: =C19*C30 -> 45.409 | E31: CALCULABLE | F31: EBITDA × entry multiple (informational)
B32: Preference settlement haircut (%) | C32: 0.51 | E32: ASSUMPTION | F32: KEY ASSUMPTION -no signal from Silverfleet; pure modelling
B33: Preference settlement amount (£m) | C33: =C27*(1-C32) -> 40.278 | E33: CALCULABLE | F33: Total pref × (1 - haircut) | P33: ACQUISITION DEBT SCHEDULE & CASH SWEEP
B34: Transaction fees (£m) | C34: 2.1 | E34: ASSUMPTION | F34: Illustrative | P34: Operating debt | Q34: =26 -> 26 | R34: =Q34 -> 26 | S34: =R38 -> 23.725663 | T34: =S38 -> 20.91508 | U34: =T38 -> 17.50477 | V34: =U38 -> 13.425254
B35: New senior debt at entry (£m) | C35: 26 | E35: ASSUMPTION | F35: Illustrative; not based on debt market sounding | P35: Debt Interest Rate | Q35: =C46 -> 0.085 | R35: =C46 -> 0.085 | S35: =R35 -> 0.085 | T35: =S35 -> 0.085 | U35: =T35 -> 0.085 | V35: =U35 -> 0.085
B36: Management rollover (£m) | C36: 2 | E36: ASSUMPTION | F36: Illustrative | P36: Cash Interest | Q36: =0 -> 0 | R36: =-R35*R34 -> -2.21 | S36: =-S35*S34 -> -2.0166813 | T36: =-T35*T34 -> -1.7777818 | U36: =-U35*U34 -> -1.4879055 | V36: =-V35*V34 -> -1.1411465
B37: Entry leverage (x EBITDA) | C37: =C35/C19 -> 4.008016 | E37: CALCULABLE | F37: New senior debt / entry EBITDA | P37: Cash sweep | Q37: 0 | R37: =-R30 -> -2.2743372 | S37: =-S30 -> -2.8105826 | T37: =-T30 -> -3.4103097 | U37: =-U30 -> -4.079517 | V37: =-V30 -> -4.824707
P38: Closing debt | Q38: 26 | R38: =SUM(R37+R34) -> 23.725663 | S38: =SUM(S37+S34) -> 20.91508 | T38: =SUM(T37+T34) -> 17.50477 | U38: =SUM(U37+U34) -> 13.425254 | V38: =SUM(V37+V34) -> 8.6005465
B39: OPERATING ASSUMPTIONS
B40: Revenue growth p.a. (%) | C40: 0.05 | E40: ASSUMPTION | F40: Illustrative; commercial aero recovery supports mid-single-digit | P40: Net debt at exit | Q40: =V38-C48 -> 5.6005465
B41: EBITDA margin -exit target (%) | C41: 0.17 | E41: ASSUMPTION | F41: Recovery toward FY19 level (18.5%); ramped linearly from entry
...
